{"author":{"id":"4a66333145a8be3a1fab83bfb67acb16b49eec9bba93a1d3ada9ca43625279f7"},"ops":[{"type":3,"author":{"id":"4a66333145a8be3a1fab83bfb67acb16b49eec9bba93a1d3ada9ca43625279f7"},"timestamp":1564990409,"nonce":"8i+/GQ/eZ69BlQM4SfFgWmVOXYg=","message":"Elindul az éjszakai cron job, és márthonhegynél lehal. Elindítottam kézzel, meglátjuk ad-e valami használható hibaüzenetet.","files":null},{"type":3,"author":{"id":"4a66333145a8be3a1fab83bfb67acb16b49eec9bba93a1d3ada9ca43625279f7"},"timestamp":1564995103,"nonce":"yOL+yDvWD1enSbL/UOE+hgjmvtg=","message":"És most lefutott hiba nélkül. Esetleg az lehet, hogy a pythonanywhere IP-jéről pont akkor futtat más is overpass query-t, és akkor hiába nézem meg a status-t, látom, hogy mehet a query és azonnal küldöm, mégis visszadob.\n\nAnnyit mindenesetre majd megteszek, hogy majd injektálok hibát és megoldom, hogy ha exceptiont dob a cron akkor az logolódjon, így okosabbak leszünk legközelebb.","files":null}]}