{"author":{"id":"4a66333145a8be3a1fab83bfb67acb16b49eec9bba93a1d3ada9ca43625279f7"},"ops":[{"type":3,"author":{"id":"4a66333145a8be3a1fab83bfb67acb16b49eec9bba93a1d3ada9ca43625279f7"},"timestamp":1567059659,"nonce":"HplDf+wS4gTflLY3igAJ+Fp6O6s=","message":"Valóban nem frissült, de más miatt:\n\n````\n2019-08-29 01:46:11 ERROR main: unhandled exception: Traceback (most recent call last):\n  File \"/home/vmiklos/git/osm-gimmisn/cron.py\", line 151, in main\n    our_main(relations, config)\n  File \"/home/vmiklos/git/osm-gimmisn/cron.py\", line 127, in our_main\n    update_street_housenumbers_ref(relations, config)\n  File \"/home/vmiklos/git/osm-gimmisn/cron.py\", line 93, in update_street_housenumbers_ref\n    relation.write_ref_housenumbers(reference)\n  File \"/home/vmiklos/git/osm-gimmisn/helpers.py\", line 412, in write_ref_housenumbers\n    lst += self.build_ref_housenumbers(memory_cache, street, suffix)\n  File \"/home/vmiklos/git/osm-gimmisn/helpers.py\", line 384, in build_ref_housenumbers\n    if street in reference[refmegye][reftelepules].keys():\nKeyError: '005'\n````\n\nMajd megnézem, mi ez.","files":null},{"type":3,"author":{"id":"4a66333145a8be3a1fab83bfb67acb16b49eec9bba93a1d3ada9ca43625279f7"},"timestamp":1567062250,"nonce":"cB/HWclxangTK6CP2V12mxNqsHI=","message":"Ja világos; a valasztas.hu referenciában mindig volt 5. kerület, míg a kiegészítőben nincs, viszont ezt nem kezelem le.","files":null}]}